2018-12-04 23:29:17,133 ERROR: Exception on /auth/login [GET] [in c:\users\shepherd\program\flask\microblog\venv\lib\site-packages\flask\app.py:1761]
Traceback (most recent call last):
  File "c:\users\shepherd\program\flask\microblog\venv\lib\site-packages\flask\app.py", line 2292, in wsgi_app
    response = self.full_dispatch_request()
  File "c:\users\shepherd\program\flask\microblog\venv\lib\site-packages\flask\app.py", line 1815, in full_dispatch_request
    rv = self.handle_user_exception(e)
  File "c:\users\shepherd\program\flask\microblog\venv\lib\site-packages\flask\app.py", line 1718, in handle_user_exception
    reraise(exc_type, exc_value, tb)
  File "c:\users\shepherd\program\flask\microblog\venv\lib\site-packages\flask\_compat.py", line 35, in reraise
    raise value
  File "c:\users\shepherd\program\flask\microblog\venv\lib\site-packages\flask\app.py", line 1813, in full_dispatch_request
    rv = self.dispatch_request()
  File "c:\users\shepherd\program\flask\microblog\venv\lib\site-packages\flask\app.py", line 1799, in dispatch_request
    return self.view_functions[rule.endpoint](**req.view_args)
  File "c:\Users\Shepherd\Program\Flask\microblog\app\auth\routes.py", line 26, in login
    return render_template('auth/login.html',title=_('Sign In'),form=form)
  File "c:\users\shepherd\program\flask\microblog\venv\lib\site-packages\flask\templating.py", line 135, in render_template
    context, ctx.app)
  File "c:\users\shepherd\program\flask\microblog\venv\lib\site-packages\flask\templating.py", line 117, in _render
    rv = template.render(context)
  File "c:\users\shepherd\program\flask\microblog\venv\lib\site-packages\jinja2\asyncsupport.py", line 76, in render
    return original_render(self, *args, **kwargs)
  File "c:\users\shepherd\program\flask\microblog\venv\lib\site-packages\jinja2\environment.py", line 1008, in render
    return self.environment.handle_exception(exc_info, True)
  File "c:\users\shepherd\program\flask\microblog\venv\lib\site-packages\jinja2\environment.py", line 780, in handle_exception
    reraise(exc_type, exc_value, tb)
  File "c:\users\shepherd\program\flask\microblog\venv\lib\site-packages\jinja2\_compat.py", line 37, in reraise
    raise value.with_traceback(tb)
  File "c:\Users\Shepherd\Program\Flask\microblog\app\templates\auth\login.html", line 2, in top-level template code
    {% import 'bootstrap/wtf.html' as wtf %}
  File "c:\Users\Shepherd\Program\Flask\microblog\app\templates\base.html", line 1, in top-level template code
    {% extends 'bootstrap/base.html' %}
  File "c:\users\shepherd\program\flask\microblog\venv\lib\site-packages\flask_bootstrap\templates\bootstrap\base.html", line 1, in top-level template code
    {% block doc -%}
  File "c:\users\shepherd\program\flask\microblog\venv\lib\site-packages\flask_bootstrap\templates\bootstrap\base.html", line 4, in block "doc"
    {%- block html %}
  File "c:\users\shepherd\program\flask\microblog\venv\lib\site-packages\flask_bootstrap\templates\bootstrap\base.html", line 20, in block "html"
    {% block body -%}
  File "c:\users\shepherd\program\flask\microblog\venv\lib\site-packages\flask_bootstrap\templates\bootstrap\base.html", line 23, in block "body"
    {% block content -%}
  File "c:\Users\Shepherd\Program\Flask\microblog\app\templates\base.html", line 48, in block "content"
    {% block app_content %}{% endblock %}
  File "c:\Users\Shepherd\Program\Flask\microblog\app\templates\auth\login.html", line 12, in block "app_content"
    <p>{{ _('New User?') }} <a href="{{ url_for('register') }}">{{ _('Click to Register!') }}</a></p>
  File "c:\users\shepherd\program\flask\microblog\venv\lib\site-packages\flask\helpers.py", line 356, in url_for
    return appctx.app.handle_url_build_error(error, endpoint, values)
  File "c:\users\shepherd\program\flask\microblog\venv\lib\site-packages\flask\app.py", line 2061, in handle_url_build_error
    reraise(exc_type, exc_value, tb)
  File "c:\users\shepherd\program\flask\microblog\venv\lib\site-packages\flask\_compat.py", line 35, in reraise
    raise value
  File "c:\users\shepherd\program\flask\microblog\venv\lib\site-packages\flask\helpers.py", line 345, in url_for
    force_external=external)
  File "c:\users\shepherd\program\flask\microblog\venv\lib\site-packages\werkzeug\routing.py", line 1776, in build
    raise BuildError(endpoint, values, method, self)
werkzeug.routing.BuildError: Could not build url for endpoint 'register'. Did you mean 'auth.register' instead?
2018-12-04 23:30:56,620 INFO: Microblog startup [in c:\Users\Shepherd\Program\Flask\microblog\app\__init__.py:68]
2018-12-05 04:03:03,346 ERROR: Exception on /auth/login [POST] [in c:\users\shepherd\program\flask\microblog\venv\lib\site-packages\flask\app.py:1761]
Traceback (most recent call last):
  File "c:\users\shepherd\program\flask\microblog\venv\lib\site-packages\flask\app.py", line 2292, in wsgi_app
    response = self.full_dispatch_request()
  File "c:\users\shepherd\program\flask\microblog\venv\lib\site-packages\flask\app.py", line 1815, in full_dispatch_request
    rv = self.handle_user_exception(e)
  File "c:\users\shepherd\program\flask\microblog\venv\lib\site-packages\flask\app.py", line 1718, in handle_user_exception
    reraise(exc_type, exc_value, tb)
  File "c:\users\shepherd\program\flask\microblog\venv\lib\site-packages\flask\_compat.py", line 35, in reraise
    raise value
  File "c:\users\shepherd\program\flask\microblog\venv\lib\site-packages\flask\app.py", line 1813, in full_dispatch_request
    rv = self.dispatch_request()
  File "c:\users\shepherd\program\flask\microblog\venv\lib\site-packages\flask\app.py", line 1799, in dispatch_request
    return self.view_functions[rule.endpoint](**req.view_args)
  File "c:\Users\Shepherd\Program\Flask\microblog\app\auth\routes.py", line 21, in login
    login_user(user, remember=form.remember_me.data)
NameError: name 'login_user' is not defined
2018-12-05 04:03:57,798 INFO: Microblog startup [in c:\Users\Shepherd\Program\Flask\microblog\app\__init__.py:68]
